Workbook

Sheet 计划单
A1: *****有限公司预成本计划单
F2: NO:
A3: 实施单位 | D3: 输电分公司 | E3: 合同编号
A4: 工程项目名称 | D4: ***110kV线路工程
A5: 工程核算成本控制指标 (单位：元)
A6: 序号 | C6: 费用名称 | D6: 费用计算依据 | E6: 预控费用金额 | F6: 分公司核实金额 | G6: 备注
A7: 一 物 资 费 用 | B7: 1 | C7: 设备费 | D7: 依据预算价或类似工程招标采购价计列 | E7: ='物资表-设备'!I6 -> 0 | G7: 详见物资表-设备
B8: 2 | C8: 装材费 | D8: 近期采购材料价格 | E8: ='物资表-装材'!I11 -> 63793.25 | G8: 详见物资表-装材
B9: 3 | C9: 消材费 | D9: 依据预算价计列 | E9: 0
B10: 4 | C10: 土建配送材料费 | D10: *年*月*市信县息价 | E10: ='物资表-土建'!I9 -> 149139.48 | G10: 详见物资表-土建
B11: 4.1 | C11: 税率3%配送材料费 | D11: *年*月*市信县息价 | E11: =0 -> 0 | I11: 494328
B12: 4.2 | C12: 税率13%配送材料费 | D12: *年*月*市信县息价 | E12: ='物资表-土建'!I9 -> 149139.48
C13: 小计 | E13: =E8+E9+E10 -> 212932.73
A14: 二 分 包 费 用 | B14: 1 | C14: 专业分包费用 | D14: 专业分包 | E14: ='基础分包测算成本对比 '!H26 -> 777641.73 | G14: 详见分包测算成本，最终费用以实际工程量为准 | I14: =E18+E30 -> 1276092.9
B15: 2 | C15: 组塔劳务分包费用 | D15: 劳务分包 | E15: =组塔分包测算成本对比!H9 -> 239689.03 | G15: 详见分包测算成本，最终费用以实际工程量为准
B16: 3 | C16: 架线劳务分包费用 | D16: 劳务分包 | E16: ='架线分包测算成本对比 '!H11 -> 209974.81 | G16: 详见分包测算成本，最终费用以实际工程量为准
B17: 4 | C17: 土石方分包费用 | D17: 专业分包 | E17: =依据1号文计算分包费用!H4*0.8 -> 0 | G17: 按预算80%，分公司自行组织分包比选，最终工程量需业主签字确认
C18: 小计 | E18: =E14+E15+E17+E16 -> 1227305.6 | G18: =E18/毛利率计算表!C5 -> 0.43750575
A19: 三 项 目 其 他 费 用 | B19: 1 | C19: 建设场地征用费用 | D19: 预列 | E19: =SUM(E20:E25) -> 576800 | G19: 按照投标文件80%计列，据实发生
B20: 1.1 | C20: 青苗费用 | E20: ='4.其他费用明细表'!D5 -> 552000 | G20: 按照投标文件80%计列，据实发生 | K20: 1123116.8 | O20: 预列费用，据实发生办理
B21: 1.2 | C21: 水土保持措施费用 | E21: ='4.其他费用明细表'!D6 -> 0 | G21: 按照投标文件80%计列，据实发生
B22: 1.3 | C22: 临时施工道路 | E22: ='4.其他费用明细表'!D7 -> 8000 | G22: 按照投标文件80%计列，据实发生
B23: 1.4 | C23: 10KV单回架空线路迁改 | E23: ='4.其他费用明细表'!D8 -> 0 | G23: 按照投标文件80%计列，据实发生 | K23: 24000 | O23: 参考工程量40m，总价包干，结算不予调整
B24: 1.5 | C24: 迁移补偿 | E24: ='4.其他费用明细表'!D9 -> 16800 | G24: 按照投标文件80%计列，据实发生
B25: 1.6 | C25: 跨越房屋补偿费 | E25: ='4.其他费用明细表'!D10 -> 0 | G25: 按照投标文件80%计列，据实发生
B26: 2 | C26: 高速公路、铁路、油气管道等协调、咨询等费用 | D26: 框架 | E26: ='6.跨越咨询费'!F8 -> 0 | G26: 跨越天然气咨询费，按照投标文件80%预列，据实结算，详见附件6
B27: 3 | C27: 跨越架搭设费用 | D27: 框架 | E27: ='3.跨越架费用明细'!F19 -> 73031 | G27: 详见跨越费用明细表
B28: 4 | C28: 工程检测费用 | D28: 预列 | E28: =工程检测费!I31 -> 33650 | G28: 预列费用据实发生，详见附表
B29: 5 | C29: 咨询费 | D29: 预列 | E29: 0 | G29: 预列费用据实发生
B30: 6 | C30: 机械使用费 | D30: 预列 | E30: ='2.机械使用费用暂列'!F10 -> 48787.312 | G30: 暂列费用，具体按实际结算
B31: 7 | C31: 其他费 | D31: 预列 | E31: =SUM(E32:E35) -> 9650 | G31: 参数测试、光缆熔接测试及三点接地等费用
B32: 7.1 | C32: 光缆熔接 | D32: 预列 | E32: ='5.其他框架费用明细'!H5 -> 6600 | G32: 详见附件
B33: 7.2 | C33: 通信光缆测试 | D33: 按照原框架列取费用 | E33: ='5.其他框架费用明细'!H6 -> 3050 | G33: 详见附件
B34: 7.3 | C34: 参数测试（线路试运） | D34: 由分公司自主实施 | E34: ='5.其他框架费用明细'!H7 -> 0 | G34: 详见附件
B35: 7.4 | C35: X光探伤 | D35: 按照原框架列取费用 | E35: ='5.其他框架费用明细'!H8 -> 0 | G35: 详见附件
C36: 小计 | E36: =E19+E26+E30+E31+E29+E28+E27 -> 741918.31
A37: 四 项 目 综 合 管 理 费 | B37: 1 | C37: 安全文明费用 | D37: 专项费用，总价控制 | E37: =79423*1.09-'基础分包测算成本对比 '!H19 -> 76237.87 | G37: 已扣除土建分包部分费用，剩余按投标报价全额计列，交由安监部控制使用
B38: 2 | C38: 临时设施费 | D38: 预列 | E38: =(4000+5000+2000)*7 -> 77000 | G38: 项目部、材料站、班组按照7个月预列
B39: 3 | C39: 项目部综合管理费 | D39: 预列 | E39: =372781*0.08*1.09 -> 32506.503 | G39: 人工费8%
B40: 4 | C40: 辅助劳务费 | D40: 预列 | E40: =E39/8*3 -> 12189.939 | G40: 人工费3%
...

Sheet 毛利率计算表
A1: =计划单!D4 -> ***110kV线路工程
A2: 时间： | D2: 金额单位：元
A3: 计划成本分析及计算办法
A4: 序号 | B4: 项目费用名称 | C4: 金额 | D4: 备注
A5: （一） | B5: 签约合同价 | C5: 2805233 | D5: 合同价
A6: 1.1 | B6: 其中：勘察设计费 | C6: =计划单!E45 -> 0 | D6: 含税，6%
A7: 1.2 | B7: 其中：监理费 | C7: =计划单!E46 -> 0 | D7: 含税，6%
A8: 1.3 | B8: 其中：其他 | C8: =计划单!E47 -> 0 | D8: 含税，6%
A9: 1.4 | B9: 其中：基本预备费 | C9: 0 | D9: 甲供材料
A10: 1.5 | B10: 其中：暂估价 | D10: 结算时需据实际签证，仅限基建工程
A11: （二） | B11: 施工费用 | C11: =C5-C6-C7-C8-C9 -> 2805233 | D11: 第二版预算施工费（含设备、物资）
A12: （三） | B12: 成本合计1 | C12: =C13+C15+C18+C19+C20+C23 -> 2433426.3 | D12: ∑3.1~3.5
A13: 3.1 | B13: 分包成本 | C13: =计划单!E18 -> 1227305.6 | D13: ="分包比例为"&E13*100&"%" -> 分包比例为43.7505752998057% | E13: =C13/C11 -> 0.43750575
B14: 控制价或中标价 | C14: =C13 -> 1227305.6 | D14: 含税，9%,
A15: 3.2 | B15: 物资成本 | C15: =C16+C17 -> 212932.73
B16: 本部采购物资 | C16: =计划单!E13 -> 212932.73 | D16: 含税13%
B17: 地方性配送物资 | D17: 含税，钢筋13%、水泥13%、商砼3%
A18: 3.3 | B18: 项目综合管理成本 | C18: =计划单!E41 -> 197934.31 | D18: 项目部管理成本
A19: 3.4 | B19: 项目其他费用 | C19: =计划单!E36 -> 741918.31 | D19: 项目其他费用
A20: 3.5 | B20: 税负成本 | C20: =C21-C22 -> 53335.351 | D20: 销项税-进项税
B21: 销项税 | C21: =计划单!E42 -> 231625 | D21: 签约合同价/1.09*0.09
B22: 进项税 | C22: =计划单!E43 -> 178289.65
A23: 4 | B23: 暂列金额 | C23: =计划单!E48 -> 0
A24: （四） | B24: 毛利润1 | C24: =C11-C12 -> 371806.72 | D24: （二）-（三）合同价扣除分包、物资、项目部、税负等项目本身成本后的金额
A25: （五） | B25: 毛利润率1 | C25: =C24/C11 -> 0.13254041 | D25: （四）/（二）
A26: （六） | B26: 其他 | C26: =C28+C27+C29 -> 0
A27: 6.1 | B27: 勘察设计费 | D27: 含税，6%
A28: 6.2 | B28: 监理费 | D28: 含税，6%
A29: 6.3 | B29: 其他 | C29: =C8+C9 -> 0 | D29: 含税，6%

Sheet 物资表-设备
A1: ='物资表-装材'!A1 -> ***110kV线路工程-物资采购控制价审批表
B2: 分公司、工程物资组： | J2: 单位：元
B3: 主材、设备、消材、土建配送材料 | F3: 预算（经营部填写） | H3: 经营控制价（经营部下达） | J3: 备注
A4: 序号 | B4: 物资名称 | C4: 型号 | D4: 单位 | E4: 数量 | F4: 含税单价 | G4: 含税合价 | H4: 含税单价 | I4: 含税合价
J5: 预算价下浮10%
B6: 合计 | G6: =SUM(G5:G5) -> 0 | I6: =SUM(I5:I5) -> 0
A7: 1.此表原则上依据单项成本管理办法计列物资总限价。
A8: 2.分公司应根据经营的成本控制价开展物资招标。
A9: 3.最高限价可分类控制，也可单项控制，原则上总费用不高于经营下达的总控制价。
A10: 公司生产分管领导： 公司经营分管领导：
A11: 经营部主任： 经营部技经专职：

Sheet 物资表-装材
A1: ='物资表-土建'!A1 -> ***110kV线路工程-物资采购控制价审批表
B2: 分公司： | J2: 单位：元
B3: 主材、设备、消材、土建配送材料 | F3: 预算（经营部填写） | H3: 经营控制价（经营部下达） | J3: 备注
A4: 序号 | B4: 物资名称 | C4: 型号 | D4: 单位 | E4: 数量 | F4: 含税单价 | G4: 含税合价 | H4: 含税单价 | I4: 含税合价
A5: 1 | B5: 镀锌圆钢 | D5: t | E5: 3.866 | F5: 3549.9967 | G5: =F5*E5 -> 13724.287 | H5: =4030*0.95 -> 3828.5 | I5: =H5*E5 -> 14800.981 | J5: 信息价下浮5%
A6: 2 | B6: 接地角钢 | C6: ∠45X45X5 | D6: t | E6: 0.875 | F6: 4499.999 | G6: =F6*E6 -> 3937.4991 | H6: =4000*0.95 -> 3800 | I6: =H6*E6 -> 3325 | J6: 投标价下浮5%
A7: 3 | B7: 地脚螺栓 | D7: t | E7: 6.777 | F7: 6999.9997 | G7: =F7*E7 -> 47438.998 | H7: 6300 | I7: =H7*E7 -> 42695.1 | J7: 近期采购价
A8: 4 | B8: 色标牌 | D8: 块 | E8: 2.03 | F8: 100.005 | G8: =F8*E8 -> 203.01015 | H8: 112 | I8: =H8*E8 -> 227.36 | J8: 近期采购价
A9: 5 | B9: 杆号牌 | D9: 块 | E9: 23.345 | F9: 100.005 | G9: =F9*E9 -> 2334.6167 | H9: 112 | I9: =H9*E9 -> 2614.64 | J9: 近期采购价
A10: 6 | B10: 镀锌型钢 | C10: 综合 | D10: t | E10: 0.034 | F10: 4499.999 | G10: =F10*E10 -> 152.99997 | H10: =4030*0.95 -> 3828.5 | I10: =H10*E10 -> 130.169 | J10: 信息价下浮5%
B11: 合计 | G11: =SUM(G5:G10) -> 67791.411 | I11: =SUM(I5:I10) -> 63793.25
A12: 1.此表原则上依据单项成本管理办法计列物资总限价。 2.分公司应根据经营的成本控制价开展物资招标。 3.最高限价可分类控制，也可单项控制，原则上总费用不高于经营下达的总控制价。 4.上述用量已含损耗。
A15: 技经审计部专职： 技经审计部负责人： 工程物资部专职： 工程物资部负责人：

Sheet 物资表-土建
A1: =计划单!D4&"-物资采购控制价审批表" -> ***110kV线路工程-物资采购控制价审批表
B2: 分公司、工程物资组： | J2: 单位：元
B3: 主材、设备、消材、土建配送材料 | F3: 预算（经营部填写） | H3: 经营控制价（经营部下达） | J3: 备注
A4: 序号 | B4: 物资名称 | C4: 型号 | D4: 单位 | E4: 数量 | F4: 含税单价 | G4: 含税合价 | H4: 含税单价 | I4: 含税合价
A5: 1 | B5: 普通硅酸盐水泥 | C5: 42.5 | D5: t | E5: 63.284 | F5: 334.9998 | G5: =F5*E5 -> 21200.127 | H5: =395*0.95 -> 375.25 | I5: =H5*E5 -> 23747.321 | J5: 信息价下浮5%
A6: 2 | B6: 商品混凝土 | C6: C25 | D6: m³ | E6: 240.76 | F6: 378.2778 | G6: =F6*E6 -> 91074.163 | H6: =435*0.95 -> 413.25 | I6: =H6*E6 -> 99494.07 | J6: 信息价下浮5%
A7: 3 | B7: 商品混凝土 | C7: C30灌 | D7: m³ | E7: 61.261 | F7: 410.1769 | G7: =F7*E7 -> 25127.847 | H7: =445*0.95 -> 422.75 | I7: =H7*E7 -> 25898.088 | J7: 信息价下浮5%
B9: 合计 | G9: =SUM(G5:G8) -> 137402.14 | I9: =SUM(I5:I8) -> 149139.48
A10: 1.此表原则上依据单项成本管理办法计列物资总限价。 2.分公司应根据经营的成本控制价开展物资招标。 3.最高限价可分类控制，也可单项控制，原则上总费用不高于经营下达的总控制价。 4.上述用量按照投标文件预列，已考虑损耗，据实发生，据实结算。
A13: 技经审计部专职： 技经审计部负责人： 工程物资部专职： 工程物资部负责人：

Sheet 依据1号文计算分包费用
A1: 专业分包 | C1: 杆塔 | E1: 架线 | G1: 土方费用
A2: 计算方式：直接费-土建配送材料费-安全文明施工费50%+价差+税金 | C2: 计算方式：直接费-装材费-安全文明施工费50%+价差+税金 | E2: 计算方式：直接费-装材费-安全文明施工费50%+价差+税金
A3: 费用名称 | B3: 金额（元） | C3: 费用名称 | D3: 金额（元） | E3: 费用名称 | F3: 金额（元） | G3: 尖峰
A4: 直接费 | B4: =架空输电线路安装工程汇总概算表!E4+架空输电线路安装工程汇总概算表!G4+架空输电线路安装工程汇总概算表!P4 -> #REF! | C4: 安装工程直接费 | D4: =架空输电线路安装工程汇总概算表!F4 -> 1733083 | E4: 安装工程直接费 | F4: =架空输电线路安装工程汇总概算表!H4+架空输电线路安装工程汇总概算表!I4+架空输电线路安装工程汇总概算表!P6 -> #REF! | G4: 合计
A5: 土建配送材料费 | B5: =架空输电线路安装工程汇总概算表!E10+架空输电线路安装工程汇总概算表!G10+架空输电线路安装工程汇总概算表!Q4 -> #REF! | C5: 拆除工程直接费 | D5: 0 | E5: 拆除工程直接费 | F5: 0
A6: 安全文明施工费 | B6: =(架空输电线路安装工程汇总概算表!E20+架空输电线路安装工程汇总概算表!G20+架空输电线路安装工程汇总概算表!R4)*0.5 -> #REF! | C6: 装材费 | D6: =架空输电线路安装工程汇总概算表!F10 -> 1412494 | E6: 装材费 | F6: =架空输电线路安装工程汇总概算表!H10+架空输电线路安装工程汇总概算表!I10 -> 606839
A7: 价差 | B7: =架空输电线路安装工程汇总概算表!E28+架空输电线路安装工程汇总概算表!G28+架空输电线路安装工程汇总概算表!S4 -> #REF! | C7: 安装工程安全文明施工费50% | D7: =架空输电线路安装工程汇总概算表!F20/2 -> 29144 | E7: 安装工程安全文明施工费50% | F7: =(架空输电线路安装工程汇总概算表!H20+架空输电线路安装工程汇总概算表!I20+架空输电线路安装工程汇总概算表!R6)/2 -> #REF!
A8: 税金 | B8: =架空输电线路安装工程汇总概算表!E35+架空输电线路安装工程汇总概算表!G35+架空输电线路安装工程汇总概算表!T4 -> #REF! | C8: 拆除工程安全文明施工费50% | D8: 0 | E8: 拆除工程安全文明施工费50% | F8: 0
A9: 分包费 | B9: =(B4-B5-B6+B7+B8) -> #REF! | C9: 安装价差 | D9: =架空输电线路安装工程汇总概算表!F28 -> 308258 | E9: 安装价差 | F9: =架空输电线路安装工程汇总概算表!H32+架空输电线路安装工程汇总概算表!I32+架空输电线路安装工程汇总概算表!S6 -> #REF!
C10: 拆除价差 | D10: 0 | E10: 拆除价差 | F10: 0
C11: 安装工程税金 | D11: =架空输电线路安装工程汇总概算表!F35 -> 204713 | E11: 安装工程税金 | F11: =架空输电线路安装工程汇总概算表!I35+架空输电线路安装工程汇总概算表!H35+架空输电线路安装工程汇总概算表!T6 -> #REF!
C12: 拆除工程税金 | D12: 0 | E12: 拆除工程税金 | F12: 0
C13: 分包费 | D13: =(D4+D5-D6-D7-D8+D9+D10+D11+D12) -> 804416 | E13: 分包费 | F13: =(F4+F5-F6-F7-F8+F9+F10+F11+F12) -> #REF!
A14: 分包费合计 | F14: =B9+D13+F13 -> #REF!

Sheet 基础分包测算成本对比 
A1: =计划单!D4 -> ***110kV线路工程 | F1: ------- | G1: 基础及接地部分--专业分包计件清单报价表
A2: 附件三 基础及接地部分 | I2: 金额单位：元
A3: 序号 | B3: 项目名称 | C3: 项目特征及工作内容 | E3: 计量单位 | F3: 工程量 | G3: 综合单价 | H3: 合价 | I3: 备注
A5: 1 | B5: 基础工程 | C5: 分项 | D5: 工作内容
C6: 大开挖 | D6: 复测及分坑、材料运输、现场检验、基础基坑土石方开挖、基面场平回填夯实、余土外运、基础钢筋制作安装、地脚螺栓安装保护、模板安装及拆除、垫层及基础浇捣，试块制作，养护．保护帽浇捣、施工机械装拆与场外运输、接地开挖敷设接地电阻测试，施工机械装拆与场外运输、清理现场、工器具移运等。 | E6: m³ | F6: 0 | G6: 905.74 | H6: =G6*F6 -> 0 | I6: 不区分保护帽、阶梯基础、大板基础、挖孔桩基础、灌注桩基础等形式。控制单价按商砼和现场搅拌已综合考虑，包含商砼泵送、现浇方式材料运输费用，综合考虑施工便道修筑费，不因改变施工方式调整单价。不因青苗阻工等窝工办理签证，围堰费用已包含所需草袋土，由分包单位承担，钢筋、水泥、砼试块等检测费用已包含其中，分包单位需提供相应报告
C7: 人工掏挖 | E7: m³ | F7: 306.36 | G7: 1283.98 | H7: =G7*F7 -> 393360.11
C8: 人工掏挖(岩石) | E8: m³ | F8: 0 | G8: 1316.98 | H8: =G8*F8 -> 0
C9: 灌注桩基础 | E9: m³ | F9: 52.36 | G9: 759 | H9: =G9*F9 -> 39741.24 | M9: 机械化道路施工+20万
C10: 旋挖桩基础 | E10: m³ | F10: 0 | G10: 679 | H10: =G10*F10 -> 0
C11: 进出场费用 | E11: 次 | F11: 1 | G11: 20000 | H11: =G11*F11 -> 20000
C12: 垫层 | E12: m³ | F12: 0 | G12: 530 | H12: =G12*F12 -> 0
C13: 护壁/保护帽 | E13: m³ | F13: 39.68 | G13: 643 | H13: =G13*F13 -> 25514.24
C14: 草袋土围堰 | E14: m³ | F14: 0 | G14: 164 | H14: =G14*F14 -> 0
C15: 钢筋制作 | D15: 基础部分钢筋制作（准备，截割，焊接，制弯，整理，捆扎，清理现场） | E15: t | F15: 22.658 | G15: =220+3351 -> 3571 | H15: =G15*F15 -> 80911.718
C16: 场地平基 | D16: 尖峰、基面、排洪（水）沟、护坡、挡土（水）墙、永久围堰、防撞墩（墙）土石方开挖，平基土方 | E16: m³ | F16: 0 | G16: =15.9*0.8 -> 12.72 | H16: =G16*F16 -> 0
C17: 护坡、挡土墙 及排洪沟 | D17: 材料移运，选料、砂浆配拌、挖方、砌筑、上浆、勾缝、模板安装及拆除、钢筋安装、混凝土搅拌及浇制、捣固、养护、排水、清理现场、工器具移运等。 | E17: m³ | F17: 74.9 | G17: 580 | H17: =G17*F17 -> 43442
C18: 接地安装费用 | D18: 基础接地安装费用，安照10元/米暂列 | E18: m | F18: 4078 | G18: 10 | H18: =G18*F18 -> 40780
A19: 2 | B19: 安全文明施工费 | D19: 措施费 | E19: 项 | F19: 1 | G19: =18960*0.5*1.09 -> 10333.2 | H19: =F19*G19 -> 10333.2 | I19: 措施项目费中的安全文明施工费应按照国家或省级、行业建设主管部门规定的费率计算，计算基数随建筑安装工程施工费的调整据实计列。施工过程中国家或省级、行业建设主管部门对安全文明施工费进行调整的，措施项目费中安全文明施工费应作相应调整。项目提取的安全文明施工费立足满足工程现场安全防护和环境改善需要，优先用于保证工程建设过程达到安全生产标准化要求所需的支出。安全文明施工费用由承包人提出申请，经安监部审核，公司领导批准后，规范、足额使用，专款专用。工程完工后，若安全文明施工费未按要求投入，发包人有权扣回
A20: 3 | B20: 施工临时道路修筑及拓宽 | D20: 机械化道路修筑 | E20: m | F20: 1880 | G20: 42.5 | H20: =G20*F20 -> 79900 | I20: 含路床整形及每米降方、水田及塔基操作面铺设钢板路基箱
A21: 4 | B21: 水土保持措施费用 | D21: 表土剥离 | E21: m³ | F21: 315.779 | G21: 3.56 | H21: =G21*F21 -> 1124.1732
D22: 表土回填 | E22: m³ | F22: 315.779 | G22: 1.15 | H22: =G22*F22 -> 363.14585
D23: 土地整治 | E23: hm² | F23: 1.177 | G23: 10960 | H23: =G23*F23 -> 12899.92
D24: 播撒草籽（含草籽费） | E24: hm² | F24: 2897.909 | G24: 0.79 | H24: =G24*F24 -> 2289.3481
D25: 造林种草（含草籽、苗木费） | E25: hm² | F25: 8875.865 | G25: 3.04 | H25: =G25*F25 -> 26982.63
C26: 报价合计 | E26: / | F26: / | H26: =SUM(H6:H25) -> 777641.73
C27: 材料供应划分：砂、石、水及耗材均由分包商自行采购，地脚螺丝、接地镀锌铁件、钢筋、水泥、商砼为甲供物资，甲供商砼由甲方负责泵送运输。
A28: 注意事项 | C28: 1、本工程人力平均运距、汽车平均运距、施工便道、余土外运应折算进单价，请现场踏勘研判折算进综合单价，不因图纸描述与实际不一致而调整结算单价；
C29: 2、本工程地形、地质、地貌等工程图纸的描述仅供参考，请现场踏勘研判折算进综合单价，不因图纸与实际不一致而调整结算单价；
C30: 3、投标人中标后，其综合单价（为完成工程量综合清单中一个规定计量单位项目所需的人工费、材料费、机械使用费、安全文明环保措施费、规费、管理费和利润、税金等，并考虑风险因素）属合同的组成部分，在合同执行期间不论发生任何情况或由于任何原因，工程结算时综合单价不再做任何调整；
C31: 4、综合单价分包部分工程结算时按报价所列综合单价乘以实际完成的工程量（竣工图设计工程量）计算。合价仅为支付款项提供依据，不做为工程结算的依据；
C32: 5、清单内容包含完成本项工作的全过程内容，包含但不仅限于文件内容。控制价编制参照《电力建设工程预算定额》（2018版）、《电网工程建设预算编制与计算规定》（2018年版）、公司相关取费文件计算。严禁涂改清单！
C33: 6、综合单价和合价采用一般计税法，税率9%。
B34: 报价总计（人民币大写）：
B35: 分包商： （全称、盖章）
B36: 法定代表人或委托代理人： （签字）
B37: 日期：
C40: =21022575 -> 21022575

Sheet 基础混凝土统计表
A1: 混凝土设计量 | B1: 混凝土标号 | C1: 掏挖 | I1: 清单量小计 | K1: 使用量（含超灌量）小计 | M1: 商砼+水泥配送物资小计 | O1: 钢筋配送物资
C2: 设计量 | D2: 浇筑方式 | E2: 设计量 | F2: 浇筑方式 | G2: 设计量 | H2: 浇筑方式 | I2: 现浇 | J2: 商砼 | K2: 现浇 | L2: 商砼 | M2: 配送42.5水泥 | N2: 商砼 | O2: 基础钢筋（t） | P2: =#REF!+#REF! -> #REF!
A3: 保护帽 | B3: C15 | C3: =#REF! -> #REF! | D3: 现浇 | F3: 现浇 | H3: 现浇 | I3: =C3+G3+E3 -> #REF! | K3: =I3 -> #REF! | L3: =J3 -> 0 | M3: =K3*0.288 -> #REF! | N3: =L3 -> 0 | O3: 接地钢筋（t） | P3: =#REF!+#REF! -> #REF!
A4: 基础垫层 | B4: C15 | C4: =#REF! -> #REF! | D4: 现浇 | F4: 现浇 | I4: =C4+G4+E4 -> #REF! | K4: =I4 -> #REF! | L4: =J4 -> 0 | M4: =K4*0.288 -> #REF! | N4: =L4 -> 0 | O4: 配送钢筋（t） | P4: =P2+P3 -> #REF!
A5: 现浇基础 | B5: C25 | C5: =#REF!+#REF! -> #REF! | D5: 现浇 | F5: 现浇 | I5: =C5+G5+E5 -> #REF! | K5: =I5 -> #REF! | L5: =J5 -> 0 | M5: =K5*0.36 -> #REF! | N5: =L5 -> 0
A6: 挖孔基础 | B6: C25 | C6: =#REF! -> #REF! | D6: 现浇 | I6: =C6+G6+E6 -> #REF! | K6: =I6 -> #REF! | L6: =J6*1.17 -> 0 | M6: =K6*0.36 -> #REF! | N6: =L6 -> 0
A7: 挖孔基础护壁 | B7: C15 | C7: =#REF! -> #REF! | D7: 现浇 | F7: 现浇 | H7: 现浇 | I7: =C7+G7+E7 -> #REF! | K7: =I7*1.17 -> #REF! | L7: =J7*1.17 -> 0 | M7: =K7*0.288 -> #REF! | N7: =L7 -> 0
A8: 灌注桩基础 | B8: C30 | D8: 现浇 | F8: 现浇 | H8: 现浇 | I8: =C8+G8+E8 -> 0 | J8: =C8+G8+E8 -> 0 | L8: =J8*1.17 -> 0 | M8: =K8*0.383 -> 0 | N8: =L8 -> 0
A9: 柔性基础 | B9: C30 | F9: 现浇 | I9: =C9+G9+E9 -> 0 | K9: =I9 -> 0 | L9: =J9 -> 0 | M9: =K9*0.383 -> 0
A10: 小计 | C10: =SUM(C3:C9) -> #REF! | E10: =SUM(E3:E8) -> 0 | G10: =SUM(G3:G8) -> 0 | I10: =SUM(I3:I9) -> #REF! | J10: =SUM(J3:J8) -> 0 | K10: =SUM(K3:K9) -> #REF! | L10: =SUM(L3:L9) -> 0 | M10: =SUM(M3:M9) -> #REF! | N10: =SUM(N3:N9) -> 0
A12: 平地、现场浇筑时、水泥钢筋甲供的控制单价测算表
A13: 混凝标号 | B13: 使用量 （含超灌量） | E13: 现浇水泥砂石水配合比 | G13: 现浇水泥砂石水配合比 | K13: 单价（分包自购材料，不含材料税3%） | O13: 合价小计（分包自购材料） | S13: 合计 （加入9%税）
B14: 小计 | C14: 商砼 | D14: 现浇 | E14: 425水泥 | F14: 砂 | G14: 425水泥 | H14: 砂 | I14: 石 | J14: 水 | K14: 425水泥 | L14: 砂 | M14: 石 | N14: 水 | O14: 425水泥 | P14: 砂 | Q14: 石 | R14: 水 | S14: /
A15: C15 | C15: =L3+L7+L4 -> 0 | D15: =K4+K3 -> #REF! | E15: =B15*0.288 -> 0 | F15: =B15*0.49 -> 0 | G15: =D15*0.288 -> #REF! | H15: =D15*0.49 -> #REF! | I15: =D15*0.84 -> #REF! | J15: =B15*0.18 -> 0 | K15: =660/1.03 -> 640.7767 | L15: =280/1.03 -> 271.84466 | M15: =150/1.03 -> 145.63107 | N15: =3/1.03 -> 2.9126214 | O15: =G15*K15 -> #REF! | P15: =H15*L15 -> #REF! | Q15: =I15*M15 -> #REF! | R15: =J15*N15 -> 0 | S15: =SUM(O15:R15)*1.09 -> #REF!
A16: C25 | C16: =L5+L6 -> 0 | D16: =K5 -> #REF! | E16: =B16*0.36 -> 0 | F16: =0.41*B16 -> 0 | G16: =D16*0.36 -> #REF! | H16: =0.447*D16 -> #REF! | I16: =0.926*D16 -> #REF! | J16: =D16*0.18 -> #REF! | K16: =705/1.03 -> 684.46602 | L16: =280/1.03 -> 271.84466 | M16: =150/1.03 -> 145.63107 | N16: =3/1.03 -> 2.9126214 | O16: =G16*K16 -> #REF! | P16: =H16*L16 -> #REF! | Q16: =I16*M16 -> #REF! | R16: =J16*N16 -> #REF! | S16: =SUM(O16:R16)*1.09 -> #REF!
A17: C30 | C17: =L8 -> 0 | D17: 0 | E17: =B17*0.383 -> 0 | F17: =0.42*B17 -> 0 | G17: =D17*0.383 -> 0 | H17: =0.42*D17 -> 0 | I17: =0.86*D17 -> 0 | J17: =B17*0.18 -> 0 | K17: =705/1.03 -> 684.46602 | L17: =280/1.03 -> 271.84466 | M17: =150/1.03 -> 145.63107 | N17: =3/1.03 -> 2.9126214 | O17: =G17*K17 -> 0 | P17: =H17*L17 -> 0 | Q17: =I17*M17 -> 0 | R17: =J17*N17 -> 0 | S17: =SUM(O17:R17)*1.09 -> 0
A18: 小计 | B18: =SUM(B15:B17) -> 0 | C18: =SUM(C15:C17) -> 0 | D18: =SUM(D15:D17) -> #REF! | E18: =SUM(E15:E17) -> 0 | F18: =SUM(F15:F17) -> 0 | G18: =SUM(G15:G17) -> #REF! | H18: =SUM(H15:H17) -> #REF! | I18: =SUM(I15:I17) -> #REF! | J18: =SUM(J15:J17) -> #REF! | K18: / | L18: / | M18: / | N18: / | O18: =SUM(O15:O17) -> #REF! | P18: =SUM(P15:P17)*1.09 -> #REF! | Q18: =SUM(Q15:Q17)*1.09 -> #REF! | R18: =SUM(R15:R17)*1.09 -> #REF! | S18: =SUM(P18:R18) -> #REF!
A19: 平地全商砼钢筋甲供-浇筑控制基准 | B19: 控制基准单价（元/m3） | C19: 清单量 总计（m3） | D19: 控制基准 总价
B20: 1016 | C20: =I10 -> #REF! | D20: =B20*C20 -> #REF!
A21: 加入自购材料后总价 | D21: =S18+D20 -> #REF!
A22: 平地、现场浇筑时、水泥钢筋甲供的控制综合单价测算表 | D22: =D21/C20 -> #REF! | E22: =D22*J29 -> #REF!
A24: 地形调整指数测算表
A25: 地形 | B25: 平地 | C25: 丘陵 | D25: 山地 | E25: 高山 | F25: 峻岭 | G25: 泥沼 | H25: 河网 | I25: 沙漠 | J25: 合计调整系数 | K25: 现场搅拌--水泥钢筋甲供调整基础分包--地形调整单价 | L25: 商砼方式-商砼钢筋甲供基础分包--地形调整单价
A26: 定额指数 | B26: 1 | C26: 1.1 | D26: 1.2 | E26: 1.4 | F26: 1.5 | G26: 1.4 | H26: 1.1 | I26: 1.3
A27: 地形 | B27: 平地 | C27: 丘陵 | D27: 山地 | E27: 高山 | F27: 峻岭 | G27: 泥沼 | H27: 河网 | I27: 沙漠
A28: 实际地形比例 | B28: 0.01 | C28: 0.789 | D28: 0.072 | E28: 0 | F28: 0 | G28: 0 | H28: 0.138 | I28: 0
A29: 实际调指数数 | B29: =B26*B28 -> 0.01 | C29: =C26*C28 -> 0.8679 | D29: =D26*D28 -> 0.0864 | E29: =E26*E28 -> 0 | F29: =F26*F28 -> 0 | G29: =G26*G28 -> 0 | H29: =H26*H28 -> 0.1518 | I29: =I26*I28 -> 0 | J29: =SUM(B29:I29) -> 1.1161 | K29: =L29+M29 -> 1389.2876 | L29: =J29*B20 -> 1133.9576 | M29: =(0.447+0.42)/2*L16*1.03+(0.926+0.86)/2*M16*1.03 -> 255.33
A32: 地质 地形 | B32: 工程地形比例 | C32: 单项分摊指标 | K32: 工程实际指标
C33: 普土 | D33: 坚土 | E33: 松砂石 | F33: 岩石 | G33: 松砂石 | H33: 岩石 | I33: 泥水 | J33: 合计 | K33: 普土 | L33: 坚土 | M33: 松砂石 | N33: 泥水 | O33: 岩石 | P33: 合计
A34: 平地 | B34: =B28 -> 0.01 | C34: 0.4 | D34: 0.4 | E34: 0.2 | G34: 0.2 | J34: 1 | K34: =$B$34*C34 -> 0.004 | L34: =$B$34*D34 -> 0.004 | M34: =$B$34*G34 -> 0.002 | N34: =$B$34*H34 -> 0 | O34: =$B$34*I34 -> 0 | P34: 0.8
A35: 丘陵 | B35: =C28 -> 0.789 | C35: 0.1 | D35: 0.6 | E35: 0.2 | F35: 0.1 | G35: 0.2 | H35: 0.1 | J35: 1 | K35: =$B$35*C35 -> 0.0789 | L35: =$B$35*D35 -> 0.4734 | M35: =$B$35*G35 -> 0.1578 | N35: =$B$35*H35 -> 0.0789 | O35: =$B$35*I35 -> 0 | P35: 0.2
A36: 山地 | B36: =D28 -> 0.072 | D36: 0.55 | E36: 0.3 | F36: 0.15 | G36: 0.3 | H36: 0.15 | J36: 1 | K36: =$B$36*C36 -> 0 | L36: =$B$36*D36 -> 0.0396 | M36: =$B$36*G36 -> 0.0216 | N36: =$B$36*H36 -> 0.0108 | O36: =$B$36*I36 -> 0 | P36: 0
A37: 高山 | B37: =G28 -> 0 | D37: 0.3 | E37: 0.5 | F37: 0.2 | G37: 0.5 | H37: 0.2 | J37: 1 | K37: =$B$37*C37 -> 0 | L37: =$B$37*D37 -> 0 | M37: =$B$37*G37 -> 0 | N37: =$B$37*H37 -> 0 | O37: =$B$37*I37 -> 0 | P37: 0
A38: 泥沼 | B38: =H28 -> 0.138 | C38: 0.3 | I38: 0.7 | J38: 1 | K38: =$B$38*C38 -> 0.0414 | L38: =$B$38*D38 -> 0 | M38: =$B$38*G38 -> 0 | N38: =$B$38*H38 -> 0 | O38: =$B$38*I38 -> 0.0966 | P38: 0
A39: 河网 | B39: =I28 -> 0 | I39: 1 | J39: 1 | K39: =$B$39*C39 -> 0 | L39: =$B$39*D39 -> 0 | M39: =$B$39*G39 -> 0 | N39: =$B$39*H39 -> 0 | O39: =$B$39*I39 -> 0 | P39: 0
A40: 合计 | B40: 1 | K40: =SUM(K34:K39) -> 0.1243 | L40: =SUM(L34:L39) -> 0.517 | M40: =SUM(M34:M39) -> 0.1814 | N40: =SUM(N34:N39) -> 0.0897 | O40: =SUM(O34:O39) -> 0.0966 | P40: =SUM(P34:P39) -> 1
C43: 工程地质定额价值标
C44: 普土 | D44: 坚土 | E44: 松砂石 | F44: 泥水 | G44: 松砂石 | H44: 流沙 | I44: 岩石 | J44: 合计
C45: =K40 -> 0.1243 | D45: =L40 -> 0.517 | E45: =K40 -> 0.1243 | F45: =L40 -> 0.517 | G45: =M40 -> 0.1814 | H45: =N40 -> 0.0897 | I45: =O40 -> 0.0966 | J45: =SUM(C45:I45) -> 1.6503
C46: 17.02 | D46: 17.02 | E46: 23.85 | F46: 125.26 | G46: 23.85 | H46: 125.26 | I46: 194.53 | J46: =SUM(C46:I46) -> 526.79
...

Sheet 组塔分包测算成本对比
A1: ='基础分包测算成本对比 '!A1 -> ***110kV线路工程 | G1: --组塔部分--劳务分包计件清单报价表
A2: 附件七-2 组塔部分 | I2: 金额单位：元
A3: 序号 | B3: 项目名称 | C3: 项目特征及工作内容 | E3: 不同工作劳务计件单价与合价 | I3: 备注
E4: 计件单位 | F4: 计件量 | G4: 计件单价 | H4: 合价
A5: 一 | B5: 组塔工程 | C5: 分项 | D5: 工作内容
A6: 1 | C6: 角钢塔 组立 | D6: 施工准备、材料运输、钢杆铁塔组合、吊装、地脚螺栓紧固及保护帽浇制、防盗防松螺栓紧固、零星补刷油漆、三牌防鸟盒安装(含更换部分)、施工机械装拆与场外运输、工器具移运、场地清理等。 | E6: t | F6: 109.798 | G6: 2183 | H6: =G6*F6 -> 239689.03 | I6: 抱杆组塔方式，改变组塔工艺而需要的吊车等器具设备进出场、便道不予签证。杆号牌安装包含因迁改引起需要更换的部分。
C8: 钢电杆 | E8: 基 | F8: 0 | G8: 14559 | H8: =G8*F8 -> 0
C9: 合价 | F9: / | G9: / | H9: =SUM(H6:H8) -> 239689.03
C10: 材料供应划分：材料甲供。
C11: 1、本工程人力平均运距、汽车平均运距，请现场踏勘研判折算进计件单价，不因图纸与实际不一致而调整结算单价；
C12: 2、本工程地形、地质、地貌等工程图纸的描述仅供参考，请现场踏勘研判折算进计件单价，不因图纸与实际不一致而调整结算单价；
C13: 3、计件单价是劳务分包人为完成劳务分包计件清单中一个规定计量单位项目所需的技工和普工的投入，仅包含人工费和税金等，在合同执行期间不论发生任何情况（特别说明除外），结算时计件单价不再做任何调整；特别说明：因劳务分包人原因引起承包人对外结算被核减结算费用，劳务分包结算时相关劳务作业项目视情况可同比例核减。
C14: 4、合价仅为付款提供依据，不做为劳务结算依据。计件劳务分包作业项目结算时按单价乘以实际完成的计件量（以竣工图设计、验收计件量为准）计算，以审定结算为准。
C15: 5、单价和合价采用一般计税法，税率3%。
B16: 报价总计（人民币大写）：
B17: 分包商： （全称、盖章）
B18: 法定代表人或委托代理人： （签字）
B19: 日期：
C32: =21022575 -> 21022575

Sheet 架线分包测算成本对比 
A1: ='基础分包测算成本对比 '!A1 -> ***110kV线路工程 | E1: --架线部分--劳务分包计件清单计价表
A2: 附件七-2 架线及拆除部分 | I2: 金额单位：元
A3: 序号 | B3: 项目名称 | C3: 项目特征及工作内容 | E3: 不同工作劳务计件单价与合价 | I3: 备注
E4: 计件单位 | F4: 计件量 | G4: 计件单价 | H4: 合价
A5: 一 | B5: 架空工程 | C5: 分项 | D5: 工作内容
A6: 1 | B6: 架线 及拆除 | C6: 1.型号、规格:JL3/G1A-240/30 2.回路数:单回路 3.相分裂数:二分裂 4.含:导引绳展放及牵、张场场地建设 | D6: 施工准备、材料运输、牵张场地建设、人力或机械牵引放线、护线及锚线、导线架设、光缆地线架设、杆塔监护、接续、跨越措施安拆监护、刚（柔）性防坠落装置、耐张串悬垂串跳线串间隔棒组合安装、紧挂线、弧垂观测、直线接头连接、引流线组合安装、附件安装、避雷器安装、三点接地、施工机械装拆与场外运输、工器具移运、场地清理等。跨越情况以现场实际情况为准。 | E6: km | F6: 3.08 | G6: =31760*1.2 -> 38112 | H6: =G6*F6 -> 117384.96 | I6: 架设、弧垂调整、拆除涉及跨越以现场为准，结算时不调整单价。废旧物资应运回，拆旧费包干。跨越导地线架设不因停电、青苗等窝工办理签证。停电跨越、跨越高速公路、跨铁路等不因跨越措施方式、方案不同办理签证。跨越电力线按停电措施考虑，若实际需要带电跨越措施、全封闭跨越架措施则另行委托并扣减原停电跨越、一般跨越定额措施费。不区分张力架线和一般架线，综合价考虑，不因施工组织方式不同而调整结算单价。
C7: 1.型号、规格:LGJ-150/25 2.回路数:单回路 3.相分裂数:无分裂 4.是否随导线同期架设:重新紧放线 | E7: km | F7: 0.681 | G7: =G6*0.2 -> 7622.4 | H7: =G7*F7 -> 5190.8544
A8: 2 | B8: 附件安装 | C8: 直线塔 | D8: 杆塔附件安装工程 | E8: 基 | F8: 0 | G8: 0 | H8: =G8*F8 -> 0
C9: 耐张塔 | E9: 基 | F9: 8 | G9: 10042 | H9: =G9*F9 -> 80336
A10: 3 | B10: 拆除 | C10: 拆除费用： | D10: 拆除导线、避雷线、金具、绝缘子、避雷器、防震锤等附件，以上拆除物资均含返库运输 | E10: 项 | F10: 1 | G10: =7063 -> 7063 | H10: =G10*F10 -> 7063 | I10: 详见附表
A11: 合计 | G11: / | H11: =SUM(H6:H10) -> 209974.81
A12: 注意事项 | C12: 材料供应划分：材料甲供。
C13: 1、本工程人力平均运距、汽车平均运距，请现场踏勘研判折算进计件单价，不因图纸与实际不一致而调整结算单价；
C14: 2、本工程地形、地质、地貌等工程图纸的描述仅供参考，请现场踏勘研判折算进计件单价，不因图纸与实际不一致而调整结算单价；
C15: 3、计件单价是劳务分包人为完成劳务分包计件清单中一个规定计量单位项目所需的技工和普工的投入，仅包含人工费和税金等，在合同执行期间不论发生任何情况（特别说明除外），结算时计件单价不再做任何调整；特别说明：因劳务分包人原因引起承包人对外结算被核减结算费用，劳务分包结算时相关劳务作业项目视情况可同比例核减。
C16: 4、合价仅为付款提供依据，不做为劳务结算依据。计件劳务分包作业项目结算时按报单价乘以实际完成的计件量（以竣工图设计、验收计件量为准）计算，以审定结算为准。
C17: 5、单价和合价采用一般计税法，税率3%。
B18: 报价总计（人民币大写）：
B19: 分包商： （全称、盖章）
B20: 法定代表人或委托代理人： （签字）
B21: 日期：
G27: 1434464.5
C33: 21022575

Sheet 2.机械使用费用暂列
A1: =计划单!D4 -> ***110kV线路工程 | F1: --机械使用暂列费用表
A2: 计算附表2-机械费用暂列表 | G2: 金额单位：元
A3: 序号 | B3: 项目名称 | C3: 费用明细 | G3: 备注
C4: 单位 | D4: 台班数 | E4: 暂列单价 | F4: 合价
A5: 1 | B5: 组塔（输电专用载重汽车 4t） | C5: 台班 | D5: 91.9476 | E5: 334.148 | F5: =E5*D5 -> 30724.107 | G5: 参照投标文件台班数计列，请参照机械结算单据实发生。
A6: 2 | B6: 架线（牵引机 一牵一） | C6: 台班 | D6: 3.322 | E6: 1351.629 | F6: =E6*D6 -> 4490.1115 | G6: 参照投标文件台班数计列，请参照机械结算单据实发生。
A7: 3 | B7: 架线（张力机 一张一） | C7: 台班 | D7: 3.322 | E7: 994.353 | F7: =E7*D7 -> 3303.2407 | G7: 参照投标文件台班数计列，请参照机械结算单据实发生。
A8: 4 | B8: 架线（牵引机 一牵二） | C8: 台班 | D8: 2.561 | E8: 2145.059 | F8: =E8*D8 -> 5493.4961 | G8: 参照投标文件台班数计列，请参照机械结算单据实发生。
A9: 5 | B9: 架线（张力机 一张二） | C9: 台班 | D9: 2.561 | E9: 1865.036 | F9: =E9*D9 -> 4776.3572 | G9: 参照投标文件台班数计列，请参照机械结算单据实发生。
A10: 合计： | C10: / | F10: =SUM(F5:F9) -> 48787.312 | G10: 按照框架据实结算，做总价控制

Sheet 3.跨越架费用明细
A1: =计划单!D4 -> ***110kV线路工程 | C1: --跨越架暂列费用表
A2: 计算附表3-跨越费用暂列表 | G2: 金额单位：元
A3: 序号 | B3: 项目名称 | C3: 费用明细 | G3: 备注
C4: 单位 | D4: 投标工程量 | E4: 框架单价 | F4: 合价
A5: 1 | B5: 低压、弱电线 | C5: 处 | D5: 4 | E5: 2340 | F5: =E5*D5 -> 9360 | G5: 以处为单位办理，按照框架价计列
A6: 2 | B6: 10kV电力线 | C6: 处 | D6: 8 | E6: 7200 | F6: =E6*D6 -> 57600 | G6: 以处为单位办理，按照框架价计列
A7: 3 | B7: 一般公路 | C7: 处 | D7: 1 | E7: 5400 | F7: =E7*D7 -> 5400 | G7: 以处为单位办理，按照框架价计列
A8: 4 | B8: 被穿越电力线电压等级:500kV（停电） | C8: 处 | D8: 0 | E8: 0 | F8: =E8*D8 -> 0 | G8: 原则应为停电施工，不计列该费用
A9: 5 | B9: 被穿越电力线电压等级:220kV（带电） | C9: 处 | D9: 0 | E9: 0 | F9: =E9*D9 -> 0 | G9: 原则应为停电施工，不计列该费用
A10: 6 | B10: 被穿越电力线电压等级:110kV（带电） | C10: 处 | D10: 0 | E10: 0 | F10: =E10*D10 -> 0 | G10: 原则应为停电施工，不计列该费用
A11: 7 | B11: 被穿越电力线电压等级:35kV（带电） | C11: 处 | D11: 0 | E11: 0 | F11: =E11*D11 -> 0 | G11: 原则应为停电施工，不计列该费用
A12: 8 | B12: 特殊跨越（铁路） | C12: 处 | D12: 0 | E12: 32400 | F12: =E12*D12 -> 0 | G12: 以处为单位办理，按照框架价计列
A13: 9 | B13: 特殊跨越（高速） | C13: 处 | D13: 0 | E13: 32400 | F13: =E13*D13 -> 0 | G13: 以处为单位办理，按照框架价计列
A14: 10 | B14: 1.被跨越物名称:水塘 2.河宽步距:50m以内 | C14: 处 | D14: 0 | E14: 653.82 | F14: =E14*D14 -> 0 | G14: 按照投标文件100%预列
A15: 11 | B15: 1.被跨越物名称:水塘 2.河宽步距:150m以内 | C15: 处 | D15: 0 | E15: 1097.87 | F15: =E15*D15 -> 0 | G15: 按照投标文件100%预列
A16: 12 | B16: 交叉跨越（房屋、民防局、棚、集装箱、亭子） | C16: 处 | D16: 2 | E16: 183.08 | F16: =E16*D16 -> 366.16 | G16: 按照投标文件100%预列
... A18: 14 | B18: 河流 | C18: 处 | D18: 1 | E18: 304.84 | F18: =E18*D18 -> 304.84 | G18: 按照投标文件100%预列
A19: 合计： | C19: / | F19: =SUM(F5:F18) -> 73031 | G19: 总价控制，据实发生

Sheet 4.其他费用明细表
A1: =计划单!D4 -> ***110kV线路工程 | E1: --其他费用表
A2: 计算附表4-其他费用明细表 | E2: 金额单位：元
A3: 序号 | B3: 项目名称 | C3: 费用明细 | E3: 备注
C4: 投标报价 | D4: 暂列价
A5: 1 | B5: 青苗费用 | C5: 690000 | D5: =C5*0.8 -> 552000 | E5: 按照投标报价80%暂列费用，据实办理。【含建设场地征用费用、林木补偿（含施工道路）、恢复林业生产条件费（含施工道路）、青苗、经济作物补偿（含施工道路）、（松树、樟树、杂树）树木砍伐费用】，按照投标报价80%暂列费用，据实办理。
A6: 2 | B6: 水土保持措施费用 | C6: 0 | D6: =C6*0.8 -> 0 | E6: 按照投标报价80%暂列费用，据实办理。
A7: 3 | B7: 临时施工道路 | C7: 10000 | D7: =C7*0.8 -> 8000 | E7: 按照投标报价80%暂列费用，据实办理。
A8: 4 | B8: 10KV单回架空线路迁改 | C8: 0 | D8: =C8*0.8 -> 0 | E8: 迁改10kv架空线150m,投标人自行考虑，结算单价不予调整、工程量双向调整
A9: 5 | B9: 迁移补偿 | C9: 21000 | D9: =C9*0.8 -> 16800 | E9: 按照投标报价80%暂列费用，据实办理。
A10: 6 | B10: 跨越房屋补偿费 | C10: 0 | D10: =C10*0.8 -> 0 | E10: 按照投标报价100%暂列费用
A11: 合计： | D11: =SUM(D5:D10) -> 576800

Sheet 5.其他框架费用明细
A1: =计划单!D4 -> ***110kV线路工程 | E1: --其他施工框架费用表
A2: 计算附表5-其他框架费用表 | I2: 金额单位：元
A3: 序号 | B3: 项目名称 | E3: 费用明细 | I3: 备注
E4: 单位 | F4: 投标工程量 | G4: 框架单价 | H4: 合价
A5: 1 | B5: 光缆熔接 | E5: 头 | F5: 2 | G5: 3300 | H5: =G5*F5 -> 6600 | I5: 按照48芯预列，实际结算以框架合同为准
A6: 2 | B6: 通信光缆测试 | E6: 条 | F6: 1 | G6: 3050 | H6: =G6*F6 -> 3050 | I6: 按照48芯预列，实际结算以框架合同为准
A7: 3 | B7: 参数测试（线路试运） | E7: 条 | F7: 1 | G7: 0 | H7: =G7*F7 -> 0 | I7: 110kV单回路原则上自主实施，220kV单回路2.69万元/条，按照原框架列取费用
A8: 4 | B8: X光探伤 | E8: 处 | F8: 0 | G8: 0 | H8: =G8*F8 -> 0 | I8: 按照投标文件80%预列
A9: 合计： | E9: / | H9: =SUM(H5:H8) -> 9650

Sheet 6.跨越咨询费
A1: =计划单!D4 -> ***110kV线路工程 | F1: --跨越咨询费用表
A2: 计算附表3-跨越费用暂列表 | G2: 金额单位：元
A3: 序号 | B3: 项目名称 | C3: 费用明细 | G3: 备注
C4: 单位 | D4: 投标工程量 | E4: 框架单价 | F4: 合价
A5: 1 | B5: 跨电气化铁路咨询措施费 | C5: 处 | D5: 0 | E5: 208358.8 | F5: =E5*D5 -> 0 | G5: 以处为单位办理，按照框架价计列
A6: 2 | B6: 跨高速公路咨询费 | C6: 处 | D6: 0 | E6: 208358.8 | F6: =E6*D6 -> 0 | G6: 以处为单位办理，按照框架价计列
A7: 3 | B7: 输电线路跨越补偿费（天然气） | C7: 处 | D7: 0 | E7: =300000*0.8 -> 240000 | F7: =E7*D7 -> 0 | G7: 按照投标文件80%计列
A8: 合计： | C8: / | F8: =SUM(F5:F7) -> 0 | G8: 总价控制，据实发生

Sheet 工程检测费
A1: =[1]计划单!D4 -> 宝塔~露西π入文华变110kV线路工程 | E1: --工程检测费暂列费用表
A2: 计算附表3-跨越费用暂列表 | G2: 金额单位：元
A3: 序号 | B3: 检测项目 | D3: 检测参数 | E3: 工作要求 | F3: 检测数量 | G3: 单位 | H3: 计费 | I3: 单项 | J3: 备注
H4: 单价（元） | I4: 合计（元）
A5: 1 | B5: 建筑原材料 | C5: 水泥 | D5: 凝结时间、安定性、强度 | E5: 按同一生产厂家、同一品种、统一代号、同一强度等级、同一批号且连续进场的水泥，袋装不超过100t 为一批，散不超过 200t 为一批，每批抽样不少于 1次。取样数量为 24kg，缩分为两等份 | F5: 1 | G5: 组 | H5: 725 | I5: 725 | J5: 200t，首检需做氯离子含量
D6: 氯离子含量 | F6: 1 | H6: 780 | I6: 780
A7: 2 | C7: 砂 | D7: 颗粒级配、含泥量、泥块含量、氯离子含量 | E7: 同产地、同规格分批验收，大型工具，应以400m3 或600t为一验收批；小型工具运输的（如拖拉机等）应以200m3 或300t为一验收批。如进货量大且质量稳定可以1000t 为一验收批 | F7: 1 | G7: 组 | H7: 1355 | I7: 1355 | J7: 首检需做碱活性
D8: 碱活性 | F8: 1 | H8: 4285 | I8: 4285
A9: 3 | C9: 石子 | D9: 颗粒级配、含泥量、泥块含量、针片状颗粒含量 | E9: 同产地、同规格分批验收，大型工具，应以400m3或600t为一验收批；小型工具运输的（如拖拉机等）应以200m3或300t为一验收批。如进货量大且质量稳定可以1000t 为一验收批。 | F9: 1 | G9: 组 | H9: 1135 | I9: 1135 | J9: 首检需做碱活性
D10: 、
D11: 碱活性 | F11: 1 | H11: 1385 | I11: 1385
A12: 4 | C12: 钢筋原材 | D12: 屈服强度、抗拉强度、伸长率、重量偏差、弯曲性能 | E12: 按照进场批次和产品的抽样检验方案确定 | F12: 5 | G12: 组 | H12: 265 | I12: 1325 | J12: 按每规格60t考虑
A13: 5 | C13: 导地线接续管与耐张线夹的压接质量检测 | D13: 握力试验 | E13: 线路中每种形式的试件不得少于3根，变电站每种形式的试件不得少于2根。 | F13: 2 | G13: 组 | H13: 2400 | I13: 4800 | J13: 新建线路
A14: 6 | C14: 焊条 | D14: 溶敷金属力学性能试验 | E14: 每批焊条检验时，按照需要数量至少在三个部位取有代表性的样品 | F14: 1 | G14: 组 | H14: 3000 | I14: 3000 | J14: 首批材料进场做一次（二选一）
A15: 7 | C15: 混凝土用水 | D15: pH 值、不溶物含量、可溶物含量、氯离子含量、硫酸根离子含量、碱含量 | E15: 地表水每6 个月检验一次，地下水每年检验一次，再生水每 3个月检验一次，在质量稳定一年后，可每6 个月检验一次；混凝土企业设备刷水每 3 个月检验一次，在质量稳定一年 | F15: 1 | G15: 组 | H15: 2145 | I15: 2145
E16: 后， 可一年检验一次；当发现水受到污染和对混凝土性能有影响时，应立即检验。采用饮用水时可不检验，采用中水、搅拌站清洗水、施工现场循环水等其他水源时，应对其成分进行检验。
A17: 8 | C17: 钢筋焊接 | D17: 外观检查、接头拉伸试验、接头弯曲试验 | E17: 每批钢筋正式焊接前；每种牌号、规格至少做 1 组试件进 | F17: 2 | G17: 组 | H17: 375 | I17: 750 | J17: 二选一
E18: 行工艺检验。非工艺检验：对焊接头的质量检验，应分批进行外观质量检查和力学性能检验，并应符合下列规定:1.在同一台班内，由同一个焊工完成的300 个同牌号、同直径钢筋焊接接头应作为一批。当同一台班内焊接的接头数量较少，可在一周之内累计计算;累计仍不足 300 个接头时，应按一批计算;2.力学性能检验时，应从每批接头中随机切取6个接头其中3 个做拉伸试验，3个做弯曲试验;3.异径钢筋接头可只
E19: 做拉伸试验;4.预埋件钢筋 T 形接头的外观质量检查，应从同一台班内完成的同类型预埋件中抽查 5%，且不得少于 10 件。
A20: 9 | C20: 钢筋机械连接 | D20: 连接接头强度试验 | E20: 接头批量加工前，各种类型和型式接头都应进行工艺检验，现场抽检应按验收批进行，同钢筋生产厂、同强度等级、同 | F20: / | G20: 组 | H20: 190 | I20: /
E21: 规格、同类型和同型式接头应以500个为一个验收批进行检验与验收，不足 500个也应作为一个验收批
A22: 10 | C22: 钢筋工艺检验 | D22: 工艺评定 | E22: 全数检查 | F22: 1 | G22: 整线 | H22: 5195 | I22: 5195
A23: 11 | C23: 地脚螺栓 | D23: 拉伸试验 | E23: 每个厂家、每种规格抽检 3 套 | F23: 5 | G23: 组 | H23: 510 | I23: 2550 | J23: 乙供需做，根据工程实际发生量确定
A24: 12 | C24: 混凝土配合比 | D24: 混凝土性能试验：坍落度或维勃稠度、容重、抗压强度等 | E24: 满足设计、施工对混凝土强度、耐久性、和易性、经济性的要求；满足相关的国家及行业标准要求 | F24: 3 | G24: 组 | H24: 1150 | I24: 3450
A25: 13 | C25: 混凝土试块抗压强度 | D25: 抗压强度 | E25: 同一配合比混凝土，取样与试件留置应符合下列规定：每拌制 100 盘且不超过100m3 时，取样不得少于 1 次；每工作 | F25: 8 | G25: 组 | H25: 70 | I25: 560
E26: 班拌制不足 100 盘时，取样不得少于 1次；连续浇筑超过1000m3 时，超过部分每 200m3 取样不得少于 1 次；每一楼层取样不得少于 1次；每次取样应至少留置 1 组试件。
A27: 14 | C27: 混凝土结构 | D27: 结构实体同条件养护试件（抗压强度） | E27: 1同条件养护试件所对应的结构构件或结构部位，应由施工、监理等各方共同选定，且同条件养护试件的取样宣均匀分布于工程施工周期内; | F27: 3 | G27: 组 | H27: 70 | I27: 210
E28: 2同条件养护试件应在混凝土浇筑人模处见证取样;
E29: 3同条件养护试件应留量在靠近相应结构构件的适当位置，并应采取相同的养护方法;
E30: 4同一强度等级的同条件养护试件不宜少于10组，且不应少于3组。每连续两层楼取样不应少于1组:每2000m2取样不得少于1组。
A31: 合计 | I31: =SUM(I5:I30) -> 33650

Sheet 拆除费
A1: 拆除工程费计价表
A2: 工程名称：万里~西河改接汪墩变110kV线路工程 | H2: 标段： 金额单位：元
A3: 序号 | B3: 项目名称 | C3: 项目特征 | D3: 计量单位 | E3: 工程量 | F3: 全费用综合单价 | G3: 合价 | H3: 备注
A4: 1 | B4: 导线架设 | C4: 1.型号、规格:185mm²以内 2.回路数:单回路 3.相分裂数:无分裂 4.运距:自行测算，结算不调整 | D4: km | E4: 0.4 | F4: 1562.368 | G4: =F4*E4 -> 624.9472
A5: 2 | B5: 避雷线架设 | C5: 1.型号、规格:100mm²以内 2.废旧物资返库运距:自行测算，结算不调整 | D5: km | E5: 0.4 | F5: 568.816 | G5: =F5*E5 -> 227.5264
A6: 3 | B6: OPGW架设 | C6: 1.型号、规格:100mm²以内 2.废旧物资返库运距:自行测算，结算不调整 | D6: km | E6: 0.4 | F6: 2972.336 | G6: =F6*E6 -> 1188.9344
A7: 4 | B7: 导线耐张金具绝缘子串 | C7: 1.电压等级:110kV 2.导线分裂数:无分裂 3.运距:自行测算，结算不调整 | D7: 组 | E7: 12 | F7: 418.488 | G7: =F7*E7 -> 5021.856
A9: 合计 | G9: =SUM(G4:G8) -> 7063.264

Sheet 架空输电线路工程乙供主材价差汇总表
A1: 安装乙供装置性材料价差汇总表
J2: 金额单位:元
A3: 编号 | B3: 材料名称 | C3: 单位 | D3: 设计用量 | E3: 损耗率（%） | F3: 单价（不含税） | H3: 合价（不含税）
F4: 预算价 | G4: 市场价 | H4: 预算价 | I4: 市场价 | J4: 价差
A5: 一 | B5: 架空输电线路本体工程
B6: 地脚螺栓 | C6: t | D6: 8.498 | E6: 0.5 | F6: 4634.6 | G6: 4643.81 | H6: 39582 | I6: 39660 | J6: 79
B7: 毛石 | C7: m³ | D7: 300 | E7: 2.5 | F7: 80 | G7: 89.32 | H7: 24600 | I7: 27466 | J7: 2866
B8: 镀锌型钢 综合 | C8: t | D8: 0.011 | E8: 6.5 | F8: 5496 | G8: 3867.26 | H8: 64 | I8: 45 | J8: -19
B9: 普通圆钢 甲沸 10以外 HPB300 接地 综合 | C9: t | D9: 0.186 | E9: 6 | F9: 3959 | G9: 3946.9 | H9: 781 | I9: 778 | J9: -2
B10: 普通圆钢 甲沸 10以内 HPB300 接地 综合 | C10: t | D10: 4.164 | E10: 6 | F10: 3959 | G10: 3946.9 | H10: 17474 | I10: 17421 | J10: -53
B11: 普通圆钢 甲沸 10以内 HPB300 综合 | C11: t | D11: 15.872 | E11: 6.5 | F11: 3959 | G11: 3946.9 | H11: 66922 | I11: 66717 | J11: -205
B12: 普通圆钢 甲沸 10以上 HPB300 综合 | C12: t | D12: 0.869 | E12: 6.5 | F12: 3959 | G12: 3946.9 | H12: 3664 | I12: 3653 | J12: -11
B13: 普通圆钢 甲沸 10以下 HRB400 综合 | C13: t | D13: 11.725 | E13: 6.5 | F13: 3959 | G13: 3997.35 | H13: 49437 | I13: 49915 | J13: 479
B14: 普通圆钢 甲沸 10以外 HRB400 综合 | C14: t | D14: 95.931 | E14: 6.5 | F14: 3959 | G14: 3715.04 | H14: 404477 | I14: 379553 | J14: -24925
B15: 冷拔一般无缝钢管 综合 | C15: t | D15: 0.245 | E15: 3 | F15: 5824 | G15: 4345 | H15: 1470 | I15: 1096 | J15: -373
B16: OPGW光缆 OPGW-24B1-100 | C16: km | D16: 8.5 | F16: 9500 | G16: 12840 | H16: 80750 | I16: 109140 | J16: 28390
B17: 塔材（高强钢） 角钢塔 | C17: t | D17: 239.645 | E17: 0.5 | F17: 5811.97 | G17: 7000 | H17: 1399774 | I17: 1685903 | J17: 286129 | K17: =G17*1.13 -> 7910 | L17: =I17*1.13 -> 1905070.4
B18: 钢芯铝绞线 JL1/G1A 240/30 | C18: t | D18: 20.273 | E18: 0.46 | F18: 11681 | G18: 16800 | H18: 237898 | I18: 342153 | J18: 104255 | K18: =G18*1.13 -> 18984 | L18: =I18*1.13 -> 386632.89
B19: 铝包钢芯铝绞线 JL/LB20A 80 | C19: t | D19: 3.466 | E19: 0.3 | F19: 12556 | G19: 12000 | H19: 43650 | I19: 41717 | J19: -1933
B20: 混凝土 C15 | C20: m³ | D20: 456.072
B21: 普通硅酸盐水泥 42.5 | C21: t | D21: 131.349 | E21: 5.6 | F21: 396 | G21: 458.41 | H21: 54927 | I21: 63584 | J21: 8657
B22: 中砂 | C22: m³ | D22: 232.141 | E22: 15.9 | F22: 65 | G22: 213.59 | H22: 17488 | I22: 57467 | J22: 39978
B23: 碎石 粒径40mm以内 | C23: m³ | D23: 398.151 | E23: 11.5 | F23: 80 | G23: 117.48 | H23: 35515 | I23: 52154 | J23: 16639
B24: 混凝土 C25 | C24: m³ | D24: 1705.808
B25: 普通硅酸盐水泥 42.5 | C25: t | D25: 614.091 | E25: 5.6 | F25: 396 | G25: 458.41 | H25: 256798 | I25: 297270 | J25: 40472
B26: 中砂 | C26: m³ | D26: 762.496 | E26: 15.9 | F26: 65 | G26: 213.59 | H26: 57443 | I26: 188757 | J26: 131314
B27: 碎石 粒径40mm以内 | C27: m³ | D27: 1579.579 | E27: 11.5 | F27: 80 | G27: 117.48 | H27: 140898 | I27: 206909 | J27: 66011
B28: 水泥砂浆 M7.5 | C28: m³ | D28: 60
B29: 普通硅酸盐水泥 42.5 | C29: t | D29: 16.08 | E29: 5.6 | F29: 396 | G29: 458.41 | H29: 6724 | I29: 7784 | J29: 1060
B30: 中砂 | C30: m³ | D30: 70.8 | E30: 15.9 | F30: 65 | G30: 213.59 | H30: 5334 | I30: 17527 | J30: 12193
B32: 小计： | H32: 2945669 | I32: 3656668 | J32: 710999
B34: 合计： | H34: 2945669 | I34: 3656668 | J34: 710999

Sheet 架空输电线路安装工程汇总概算表
A1: 表N.11 架空输电线路安装工程汇总概算表
A2: 表二 | M2: 金额单位:元
A3: 序号 | B3: 工程或费用名称 | C3: 取费基数 | D3: 费率% | E3: 基础工程 | F3: 杆塔工程 | G3: 接地工程 | H3: 架线工程 | I3: 附件工程 | J3: 辅助工程 | K3: 合计 | L3: 各项占总计% | M3: 单位投资元/km | O3: 辅助工程 | P3: 直接费 | Q3: 装材费 | R3: 安全费 | S3: 价差 | T3: 税金
A4: 一 | B4: 直接费 | D4: 100 | E4: 3686358 | F4: 1733083 | G4: 539561 | H4: 703696 | I4: 440224 | J4: 163924 | K4: 7266845 | L4: 62.77 | M4: 1062248.9 | O4: 基础 | P4: =#REF!+#REF!+#REF! -> #REF! | Q4: =#REF! -> #REF! | R4: =#REF!+#REF!+#REF! -> #REF! | S4: =#REF!+#REF!+#REF! -> #REF! | T4: =#REF!+#REF!+#REF! -> #REF!
A5: 1 | B5: 直接工程费 | D5: 100 | E5: 3279988 | F5: 1641913 | G5: 487881 | H5: 648620 | I5: 403948 | J5: 143792 | K5: 6606142 | L5: 57.06 | M5: 965669.01 | O5: 杆塔
A6: 1.1 | B6: 定额直接费 | D6: 100 | E6: 2151242 | F6: 229419 | G6: 244047 | H6: 286322 | I6: 159407 | J6: 107080 | K6: 3177516 | L6: 27.45 | M6: 464481.29 | O6: 架线 | P6: =#REF! -> #REF! | Q6: 0 | R6: =#REF! -> #REF! | S6: =#REF! -> #REF! | T6: =#REF! -> #REF!
A7: 1.1.1 | B7: 人工费 | D7: 100 | E7: 1572583 | F7: 187830 | G7: 193465 | H7: 142249 | I7: 121159 | J7: 84386 | K7: 2301672 | L7: 19.88 | M7: 336452.55
A8: 1.1.2 | B8: 材料费 | D8: 100 | E8: 225735 | F8: 1963 | G8: 2174 | H8: 47010 | I8: 2697 | J8: 1921 | K8: 281499 | L8: 2.43 | M8: 41148.835
A9: 1.1.3 | B9: 施工机械使用费 | D9: 100 | E9: 352924 | F9: 39626 | G9: 48407 | H9: 97063 | I9: 35552 | J9: 20773 | K9: 594345 | L9: 5.13 | M9: 86879.902
A10: 1.2 | B10: 装置性材料费 | D10: 100 | E10: 1128746 | F10: 1412494 | G10: 243834 | H10: 362298 | I10: 244541 | J10: 36712 | K10: 3428625 | L10: 29.62 | M10: 501187.73
A11: 1.2.1 | B11: 甲供装置性材料费 | D11: 100
A12: 1.2.2 | B12: 乙供装置性材料费 | D12: 100 | E12: 1128746 | F12: 1412494 | G12: 243834 | H12: 362298 | I12: 244541 | J12: 36712 | K12: 3428625 | L12: 29.62 | M12: 501187.73
A13: 2 | B13: 措施费 | D13: 100 | E13: 406370 | F13: 91169 | G13: 51680 | H13: 55077 | I13: 36276 | J13: 20132 | K13: 660703 | L13: 5.71 | M13: 96579.935
A14: 2.1 | B14: 冬雨季施工增加费 | D14: 3.57 | E14: 56141 | F14: 6706 | G14: 6907 | H14: 5078 | I14: 4325 | J14: 3013 | K14: 82170 | L14: 0.71 | M14: 12011.356
A15: 2.2 | B15: 夜间施工增加费
A16: 2.3 | B16: 施工工具用具使用费 | D16: 3.82 | E16: 60073 | F16: 7175 | G16: 7390 | H16: 5434 | I16: 4628 | J16: 3224 | K16: 87924 | L16: 0.76 | M16: 12852.487
A17: 2.4 | B17: 特殊地区施工增加费
A18: 2.5 | B18: 临时设施费 | D18: 6.35 | E18: 136604 | F18: 14568 | G18: 15497 | H18: 18181 | I18: 10122 | J18: 6800 | K18: 201772 | L18: 1.74 | M18: 29494.562
A19: 2.6 | B19: 施工机构迁移费 | D19: 2.36 | E19: 37113 | F19: 4433 | G19: 4566 | H19: 3357 | I19: 2859 | J19: 1992 | K19: 54319 | L19: 0.47 | M19: 7940.28
A20: 2.7 | B20: 安全文明施工费 | D20: 3.55 | E20: 116440 | F20: 58288 | G20: 17320 | H20: 23026 | I20: 14340 | J20: 5105 | K20: 234518 | L20: 2.03 | M20: 34281.25
A21: 二 | B21: 间接费 | D21: 100 | E21: 1171339 | F21: 139614 | G21: 143884 | H21: 106927 | I21: 90178 | J21: 62766 | K21: 1714708 | L21: 14.81 | M21: 250651.62
A22: 1 | B22: 规费 | D22: 100 | E22: 586180 | F22: 70014 | G22: 72114 | H22: 53023 | I22: 45162 | J22: 31455 | K22: 857948 | L22: 7.41 | M22: 125412.69
A23: 1.1 | B23: 社会保险费 | D23: 23.5 | E23: 388035 | F23: 46347 | G23: 47738 | H23: 35100 | I23: 29896 | J23: 20822 | K23: 567938 | L23: 4.91 | M23: 83019.667
A24: 1.2 | B24: 住房公积金 | D24: 12 | E24: 198145 | F24: 23667 | G24: 24377 | H24: 17923 | I24: 15266 | J24: 10633 | K24: 290011 | L24: 2.51 | M24: 42393.021
A25: 2 | B25: 企业管理费 | D25: 35.76 | E25: 562356 | F25: 67168 | G25: 69183 | H25: 50868 | I25: 43326 | J25: 30176 | K25: 823078 | L25: 7.11 | M25: 120315.43
A26: 3 | B26: 施工企业配合调试费 | D26: 1.06 | E26: 22803 | F26: 2432 | G26: 2587 | H26: 3035 | I26: 1690 | J26: 1135 | K26: 33682 | L26: 0.29 | M26: 4923.502
A27: 三 | B27: 利润 | D27: 5 | E27: 242885 | F27: 93635 | G27: 34172 | H27: 40531 | I27: 26520 | J27: 11335 | K27: 449078 | L27: 3.88 | M27: 65645.028
A28: 四 | B28: 编制基准期价差 | D28: 100 | E28: 475537 | F28: 308258 | G28: 23114 | H28: 153224 | I28: 14485 | J28: 26265 | K28: 1000883 | L28: 8.65 | M28: 146306.46
A29: 1 | B29: 人工价差 | D29: 100 | E29: 167480 | F29: 20004 | G29: 20604 | H29: 15150 | I29: 12903 | J29: 8987 | K29: 245128 | L29: 2.12 | M29: 35832.196
... A32: 4 | B32: 装置性材料价差 | D32: 100 | E32: 278487 | F32: 286129 | G32: -75 | H32: 130712 | I32: -373 | J32: 16119 | K32: 710999 | L32: 6.14 | M32: 103932
A33: 4.1 | B33: 甲供装置性材料价差 | D33: 100
A34: 4.2 | B34: 乙供装置性材料价差 | D34: 100 | E34: 278487 | F34: 286129 | G34: -75 | H34: 130712 | I34: -373 | J34: 16119 | K34: 710999 | L34: 6.14 | M34: 103932
A35: 五 | B35: 税金 | D35: 9 | E35: 501851 | F35: 204713 | G35: 66666 | H35: 90394 | I35: 51427 | J35: 23786 | K35: 938836 | L35: 8.11 | M35: 137236.68
A36: 六 | B36: 设备费 | D36: 100 | I36: 186346 | K36: 186346 | L36: 1.61 | M36: 27239.643
A37: 1 | B37: 乙供设备不含税价 | D37: 100 | I37: 186346 | K37: 186346 | L37: 1.61 | M37: 27239.643
A38: 2 | B38: 甲供设备含税价 | D38: 100
A39: 九 | B39: 总计 | D39: 100 | E39: 6077969 | F39: 2479302 | G39: 807397 | H39: 1115295 | I39: 809179 | J39: 288076 | K39: 11577219 | L39: 100 | M39: 1692328.4
B41: 合计 | E41: 6077969 | F41: 2479302 | G41: 807397 | H41: 1115295 | I41: 809179 | J41: 288076 | K41: 11577219 | L41: 100 | M41: 1692328.4
B42: 各项占合计（%） | E42: 52 | F42: 21 | G42: 7 | H42: 10 | I42: 7 | J42: 2 | K42: 100
B43: 单位投资（元/km） | E43: 888462 | F43: 362418 | G43: 118023 | H43: 163031 | I43: 118284 | J43: 42110 | K43: 1692328

Sheet 架空输电线路单位工程预算表
A1: 表N.12 架空输电线路单位工程概算表
A2: 表三 | M2: 金额单位:元
A3: 序号 | B3: 编制依据 | C3: 项目名称及规格 | D3: 单位 | E3: 数量 | F3: 单价 | J3: 合价
F4: 装置性材料/设备 | G4: 安装费 | J4: 装置性材料/设备 | K4: 安装费
G5: 合计 | H5: 其中：人工费 | I5: 其中：机械费 | K5: 合计 | L5: 其中：人工费 | M5: 其中：机械费
A6: 一 | C6: 架空输电线路本体工程 | J6: 10776664 | K6: 24290750 | L6: 3900013 | M6: 1090598
A7: 1 | C7: 基础工程 | J7: 1646124 | K7: 8494345 | L7: 2117090 | M7: 450581
A8: 1.1 | C8: 基础工程材料工地运输 | K8: 2400405 | L8: 971858 | M8: 99087
C9: 金具、绝缘子、零星钢材：
B10: YX1-17 | C10: 人力运输 金具、绝缘子、零星钢材 | D10: t.km | E10: 63.943 | G10: 131.28 | H10: 123 | I10: 8.28 | K10: 8394 | L10: 7865 | M10: 529
B11: YX1-97 | C11: 汽车运输 金具、绝缘子、零星钢材 装卸 | D11: t | E11: 127.887 | G11: 46.02 | H11: 12.61 | I11: 26.19 | K11: 5885 | L11: 1613 | M11: 3349
B12: YX1-98 | C12: 汽车运输 金具、绝缘子、零星钢材 运输 | D12: t.km | E12: 1534.638 | G12: 1.53 | H12: 0.51 | I12: 1.02 | K12: 2348 | L12: 783 | M12: 1565
C13: 其他建筑安装材料：
B14: YX1-22 | C14: 人力运输 其他建筑安装材料 | D14: t.km | E14: 7177.755 | G14: 113.84 | H14: 106.54 | I14: 7.3 | K14: 817116 | L14: 764718 | M14: 52398
B15: YX1-107 | C15: 汽车运输 其他建筑安装材料 装卸 | D15: t | E15: 1463.693 | G15: 27.46 | H15: 9.59 | I15: 17.87 | K15: 40193 | L15: 14037 | M15: 26156
B16: YX1-108 | C16: 汽车运输 其他建筑安装材料 运输 | D16: t.km | E16: 17564.311 | G16: 1.16 | H16: 0.41 | I16: 0.75 | K16: 20375 | L16: 7201 | M16: 13173
C17: 地形系数增加--特征段1--工地运输（人力运输）金具、绝缘子、零星钢材、塔材、其他建筑安装材料（不含机械费） | D17: % | E17: 22.6 | G17: 772583.01 | H17: 772583.01 | K17: 174604 | L17: 174604
C18: 地形系数增加--特征段1--工地运输拖拉机、汽车运输（不含装卸，沙漠地形没有正式公路时使用） | D18: % | E18: 13 | G18: 22722.6 | H18: 7984.03 | I18: 14738.56 | K18: 2954 | L18: 1038 | M18: 1916
C19: 小计： | K19: 1071869 | L19: 971858 | M19: 99087
B21: 一 | C21: 直接费 | E21: 100 | G21: 1272739.9 | K21: 1272740
B22: 1 | C22: 直接工程费 | E22: 100 | G22: 1071868.7 | K22: 1071869
B23: 1.1 | C23: 定额直接费 | E23: 100 | G23: 1071868.7 | K23: 1071869
B24: 1.1.1 | C24: 人工费 | E24: 100 | G24: 971858.19 | K24: 971858
B25: 1.1.2 | C25: 材料费 | E25: 100 | G25: 923.34 | K25: 923
B26: 1.1.3 | C26: 施工机械使用费 | E26: 100 | G26: 99087.19 | K26: 99087
B27: 2 | C27: 措施费 | E27: 100 | G27: 200871.18 | K27: 200871
B28: 2.1 | C28: 冬雨季施工增加费 | E28: 3.57 | G28: 971858.19 | K28: 34695
B29: 2.3 | C29: 施工工具用具使用费 | E29: 3.82 | G29: 971858.19 | K29: 37125
B30: 2.5 | C30: 临时设施费 | E30: 6.35 | G30: 1071868.7 | K30: 68064
B31: 2.6 | C31: 施工机构迁移费 | E31: 2.36 | G31: 971858.19 | K31: 22936
B32: 2.7 | C32: 安全文明施工费 | E32: 3.55 | G32: 1071868.7 | K32: 38051
... B47: 十 | C47: 合计 | E47: 100 | G47: 2400405.3 | K47: 2400405
A49: 1.2 | C49: 基础土石方工程 | K49: 968492 | L49: 315753 | M49: 96785
C50: 线路复测及分坑：
B51: YX2-6 | C51: 线路复测及分坑 直线自立塔 | D51: 基 | E51: 31 | G51: 76.56 | H51: 41.76 | I51: 2.58 | K51: 2373 | L51: 1295 | M51: 80
B52: YX2-7 | C52: 线路复测及分坑 耐张（转角）自立塔 | D52: 基 | E52: 30 | G52: 103.96 | H52: 62.62 | I52: 3.74 | K52: 3119 | L52: 1879 | M52: 112
C53: 泥水：
B54: YX2-50 | C54: 电杆坑、塔坑、拉线坑人工挖方（或爆破）及回填 泥水 坑深4.0m以内 | D54: m³ | E54: 3261.44 | G54: 93.43 | H54: 49.15 | I54: 24.8 | K54: 304716 | L54: 160300 | M54: 80884
C55: 松砂石：
B56: YX2-134 | C56: 挖孔基础人工挖方（或爆破） 松砂石 坑径1500mm以内 坑深5m以内 | D56: m³ | E56: 2176.514 | G56: 53.47 | H56: 44.09 | I56: 4.94 | K56: 116378 | L56: 95963 | M56: 10752
...

Sheet 架空输电线路单位工程预算表（余物清理表三） (2)
A1: 架空线路单位工程预算表（余物清理工程）
A2: 表三 | M2: 金额单位:元
A3: 序号 | B3: 编制依据 | C3: 项目名称及规格 | D3: 单位 | E3: 数量 | F3: 单价 | J3: 合价
F4: 装置性材料 | G4: 安装费 | J4: 装置性材料 | K4: 安装费
G5: 合计 | H5: 其中：人工费 | I5: 其中：机械费 | K5: 合计 | L5: 其中：人工费 | M5: 其中：机械费
A6: 2 | C6: 安装工程 | K6: 88969
A7: 2.3 | C7: 输电线路及通信线路 | K7: 88969
A8: 2.3.2 | C8: (2)拆除后不能利用 | D8: % | E8: 35 | K8: 88969
B9: YX4-8 | C9: 混凝土杆组立 双杆 分段式 每基重量6.0t以内 | D9: 基 | E9: 11 | G9: 1280.3 | H9: 840.27 | I9: 382.02 | K9: 14083 | L9: 9243 | M9: 4202
B10: YX4-41 | C10: 角钢塔组立 塔全高30m以内 每米塔重400kg以内 | D10: t | E10: 38 | G10: 571.02 | H10: 499.35 | I10: 63.73 | K10: 21699 | L10: 18975 | M10: 2422
B11: YX5-44 | C11: 张力放、紧线 交流线路 导线 2×300mm²以内 | D11: km | E11: 3.872 | G11: 13663.34 | H11: 5416.96 | I11: 7912.09 | K11: 52904 | L11: 20974 | M11: 30636
B12: YX6-5 | C12: 耐张转角杆塔导线挂线及绝缘子串安装 220kV 双分裂 | D12: 组 | E12: 66 | G12: 1882.77 | H12: 1523.73 | I12: 331.33 | K12: 124263 | L12: 100566 | M12: 21868
B13: YX1-20 | C13: 人力运输 角钢塔材 | D13: t.km | E13: 1.9 | G13: 157.47 | H13: 146.52 | I13: 10.95 | K13: 299 | L13: 278 | M13: 21
B14: YX1-103 | C14: 汽车运输 角钢塔材 装卸 | D14: t | E14: 38 | G14: 49.91 | H14: 12.76 | I14: 36.56 | K14: 1897 | L14: 485 | M14: 1389
B15: YX1-104 | C15: 汽车运输 角钢塔材 运输 | D15: t.km | E15: 380 | G15: 1.57 | H15: 0.55 | I15: 1.02 | K15: 597 | L15: 209 | M15: 388
B16: YX1-13 | C16: 人力运输 线材 每件重700kg以内 | D16: t.km | E16: 1.314 | G16: 221.6 | H16: 205.24 | I16: 16.36 | K16: 291 | L16: 270 | M16: 21
B17: YX1-84 | C17: 汽车运输 线材 每件重700kg以内 运输 | D17: t.km | E17: 262.754 | G17: 1.42 | H17: 0.37 | I17: 1.05 | K17: 373 | L17: 97 | M17: 276
B18: YX1-85 | C18: 汽车运输 线材 每件重1000kg以内 装卸 | D18: t | E18: 26.275 | G18: 61.82 | H18: 11.72 | I18: 49.94 | K18: 1624 | L18: 308 | M18: 1312
C19: 小计： | K19: 218030 | L19: 151406 | M19: 62535
B21: 一 | C21: 直接费 | E21: 100 | G21: 254195.72 | K21: 254196
B22: 1 | C22: 直接工程费 | E22: 100 | G22: 218030.32 | K22: 218030
B23: 1.1 | C23: 定额直接费 | E23: 100 | G23: 218030.32 | K23: 218030
B24: 1.1.1 | C24: 人工费 | E24: 100 | G24: 151406.03 | K24: 151406
B25: 1.1.2 | C25: 材料费 | E25: 100 | G25: 4089.68 | K25: 4090
B26: 1.1.3 | C26: 施工机械使用费 | E26: 100 | G26: 62534.6 | K26: 62535
B27: 2 | C27: 措施费 | E27: 100 | G27: 36165.4 | K27: 36165
B28: 2.1 | C28: 冬雨季施工增加费 | E28: 3.57 | G28: 151406.03 | K28: 5405
B29: 2.3 | C29: 施工工具用具使用费 | E29: 3.82 | G29: 151406.03 | K29: 5784
B30: 2.5 | C30: 临时设施费 | E30: 6.35 | G30: 218030.32 | K30: 13845
B31: 2.6 | C31: 施工机构迁移费 | E31: 2.24 | G31: 151406.03 | K31: 3391
B32: 2.7 | C32: 安全文明施工费 | E32: 3.55 | G32: 218030.32 | K32: 7740
B33: 二 | C33: 合计 | E33: 100 | G33: 254195.72 | K33: 254196
C34: 余物清理费： | D34: % | E34: 35 | G34: 254195.72 | K34: 88969

Sheet 架空输电线路单位工程预算表（余物清理表三）
A1: 架空线路单位工程预算表（余物清理工程）
A2: 表三 | M2: 金额单位:元
A3: 序号 | B3: 编制依据 | C3: 项目名称及规格 | D3: 单位 | E3: 数量 | F3: 单价 | J3: 合价
F4: 装置性材料 | G4: 安装费 | J4: 装置性材料 | K4: 安装费
G5: 合计 | H5: 其中：人工费 | I5: 其中：机械费 | K5: 合计 | L5: 其中：人工费 | M5: 其中：机械费
A6: 2 | C6: 安装工程 | K6: 88969
A7: 2.3 | C7: 输电线路及通信线路 | K7: 88969
A8: 2.3.2 | C8: (2)拆除后不能利用 | D8: % | E8: 35 | K8: 88969
B9: YX4-8 | C9: 混凝土杆组立 双杆 分段式 每基重量6.0t以内 | D9: 基 | E9: 11 | G9: 1280.3 | H9: 840.27 | I9: 382.02 | K9: 14083 | L9: 9243 | M9: 4202
B10: YX4-41 | C10: 角钢塔组立 塔全高30m以内 每米塔重400kg以内 | D10: t | E10: 38 | G10: 571.02 | H10: 499.35 | I10: 63.73 | K10: 21699 | L10: 18975 | M10: 2422
B11: YX5-44 | C11: 张力放、紧线 交流线路 导线 2×300mm²以内 | D11: km | E11: 3.872 | G11: 13663.34 | H11: 5416.96 | I11: 7912.09 | K11: 52904 | L11: 20974 | M11: 30636
B12: YX6-5 | C12: 耐张转角杆塔导线挂线及绝缘子串安装 220kV 双分裂 | D12: 组 | E12: 66 | G12: 1882.77 | H12: 1523.73 | I12: 331.33 | K12: 124263 | L12: 100566 | M12: 21868
B13: YX1-20 | C13: 人力运输 角钢塔材 | D13: t.km | E13: 1.9 | G13: 157.47 | H13: 146.52 | I13: 10.95 | K13: 299 | L13: 278 | M13: 21
B14: YX1-103 | C14: 汽车运输 角钢塔材 装卸 | D14: t | E14: 38 | G14: 49.91 | H14: 12.76 | I14: 36.56 | K14: 1897 | L14: 485 | M14: 1389
B15: YX1-104 | C15: 汽车运输 角钢塔材 运输 | D15: t.km | E15: 380 | G15: 1.57 | H15: 0.55 | I15: 1.02 | K15: 597 | L15: 209 | M15: 388
B16: YX1-13 | C16: 人力运输 线材 每件重700kg以内 | D16: t.km | E16: 1.314 | G16: 221.6 | H16: 205.24 | I16: 16.36 | K16: 291 | L16: 270 | M16: 21
B17: YX1-84 | C17: 汽车运输 线材 每件重700kg以内 运输 | D17: t.km | E17: 262.754 | G17: 1.42 | H17: 0.37 | I17: 1.05 | K17: 373 | L17: 97 | M17: 276
B18: YX1-85 | C18: 汽车运输 线材 每件重1000kg以内 装卸 | D18: t | E18: 26.275 | G18: 61.82 | H18: 11.72 | I18: 49.94 | K18: 1624 | L18: 308 | M18: 1312
C19: 小计： | K19: 218030 | L19: 151406 | M19: 62535
B21: 一 | C21: 直接费 | E21: 100 | G21: 254195.72 | K21: 254196
B22: 1 | C22: 直接工程费 | E22: 100 | G22: 218030.32 | K22: 218030
B23: 1.1 | C23: 定额直接费 | E23: 100 | G23: 218030.32 | K23: 218030
B24: 1.1.1 | C24: 人工费 | E24: 100 | G24: 151406.03 | K24: 151406
B25: 1.1.2 | C25: 材料费 | E25: 100 | G25: 4089.68 | K25: 4090
B26: 1.1.3 | C26: 施工机械使用费 | E26: 100 | G26: 62534.6 | K26: 62535
B27: 2 | C27: 措施费 | E27: 100 | G27: 36165.4 | K27: 36165
B28: 2.1 | C28: 冬雨季施工增加费 | E28: 3.57 | G28: 151406.03 | K28: 5405
B29: 2.3 | C29: 施工工具用具使用费 | E29: 3.82 | G29: 151406.03 | K29: 5784
B30: 2.5 | C30: 临时设施费 | E30: 6.35 | G30: 218030.32 | K30: 13845
B31: 2.6 | C31: 施工机构迁移费 | E31: 2.24 | G31: 151406.03 | K31: 3391
B32: 2.7 | C32: 安全文明施工费 | E32: 3.55 | G32: 218030.32 | K32: 7740
B33: 二 | C33: 合计 | E33: 100 | G33: 254195.72 | K33: 254196
C34: 余物清理费： | D34: % | E34: 35 | G34: 254195.72 | K34: 88969
